<?xml version="1.0"?>
<robot name="ranger_1s_urdf">

  <link name="base_link">
  </link>
  
  <link name="chassis_link">
    <inertial>
      <origin xyz="-0.00310088531991259 0 -0.231217404581497" rpy="0 0 0" />
      <mass value="1746.43926444" />
      <inertia ixx="571.534910317483" ixy="1.38173028539407E-15" ixz="-1.65507449540624" iyy="651.75829633574" iyz="-1.38127598443795E-14" izz="1154.91593661341" />
    </inertial>
    <visual>
      <origin xyz="0 0 0" rpy="0 0 0" />
      <geometry>
        <mesh filename="package://vitrox_project/meshes/chassis_link.STL" />
      </geometry>
      <material name="">
        <color rgba="0.792156862745098 0.819607843137255 0.933333333333333 1" />
      </material>
    </visual>
    <collision>
      <origin xyz="0 0 0" rpy="0 0 0" />
      <geometry>
        <mesh filename="package://vitrox_project/meshes/chassis_link.STL" />
      </geometry>
    </collision>
  </link>

  <joint name="chassis_joint" type="fixed">
    <parent link="base_link" />
    <child link="chassis_link" />
    <origin xyz="0 0 0" />
  </joint>

  <link name="wheel_holder_link">
    <inertial>
      <origin xyz="1.66533453693773E-16 0 -0.199440219087338" rpy="0 0 0" />
      <mass value="23.1310120065877" />
      <inertia ixx="0.606465937486971" ixy="6.24500451351651E-17" ixz="1.35875314883623E-16" iyy="0.614610947650548" iyz="1.07529255062108E-16" izz="0.336166441859387" />
    </inertial>
    <visual>
      <origin xyz="0 0 0" rpy="0 0 0" />
      <geometry>
        <mesh filename="package://vitrox_project/meshes/wheel_holder_link.STL" />
      </geometry>
      <material name="">
        <color rgba="0.792156862745098 0.819607843137255 0.933333333333333 1" />
      </material>
    </visual>
    <collision>
      <origin xyz="0 0 0" rpy="0 0 0" />
      <geometry>
        <mesh filename="package://vitrox_project/meshes/wheel_holder_link.STL" />
      </geometry>
    </collision>
  </link>

  <joint name="wheel_holder_joint" type="continuous">
    <origin xyz="0.65801 0.7012 -0.64077" rpy="0 0 0" />
    <parent link="chassis_link" />
    <child link="wheel_holder_link" />
    <axis xyz="0 0 1" />
    <limit lower="0" upper="0" effort="0" velocity="0" />
    <dynamics damping="0.1" friction="0.1" />
  </joint>

  <link name="wheel_link">
    <inertial>
      <origin xyz="-5.55111512312578E-17 0 -0.0484999999999998" rpy="0 0 0" />
      <mass value="10.3070752937469" />
      <inertia ixx="0.0955484931412841" ixy="2.31995155979365E-18" ixz="0" iyy="0.0955484931412841" iyz="-2.9265790442115E-18" izz="0.176557804898947" />
    </inertial>
    <visual>
      <origin xyz="0 0 0" rpy="0 0 0" />
      <geometry>
        <mesh filename="package://vitrox_project/meshes/wheel_link.STL" />
      </geometry>
      <material name="">
        <color rgba="0.792156862745098 0.819607843137255 0.933333333333333 1" />
      </material>
    </visual>
    <collision>
      <origin xyz="0 0 0" rpy="0 0 0" />
      <geometry>
        <mesh filename="package://vitrox_project/meshes/wheel_link.STL" />
      </geometry>
    </collision>
  </link>

  <joint name="wheel_joint" type="continuous">
    <origin xyz="0 -0.0485 -0.35" rpy="1.5708 0 0" />
    <parent link="wheel_holder_link" />
    <child link="wheel_link" />
    <axis xyz="0 0 -1" />
    <dynamics damping="0.1" friction="0.1" />
  </joint>

  <link name="wheel_holder_link_1">
    <inertial>
      <origin xyz="4.44089209850063E-16 -8.88178419700125E-16 -0.199440219087338" rpy="0 0 0" />
      <mass value="23.1310120065877" />
      <inertia ixx="0.606465937486973" ixy="7.28583859910259E-17" ixz="-4.56379468440948E-18" iyy="0.614610947650549" iyz="2.10575546353402E-17" izz="0.336166441859387" />
    </inertial>
    <visual>
      <origin xyz="0 0 0" rpy="0 0 0" />
      <geometry>
        <mesh filename="package://vitrox_project/meshes/wheel_holder_link_1.STL" />
      </geometry>
      <material name="">
        <color rgba="0.792156862745098 0.819607843137255 0.933333333333333 1" />
      </material>
    </visual>
    <collision>
      <origin xyz="0 0 0" rpy="0 0 0" />
      <geometry>
        <mesh filename="package://vitrox_project/meshes/wheel_holder_link_1.STL" />
      </geometry>
    </collision>
  </link>

  <joint name="wheel_holder_joint_1" type="continuous">
    <origin xyz="-0.79256 0.7012 -0.64077" rpy="0 0 0" />
    <parent link="chassis_link" />
    <child link="wheel_holder_link_1" />
    <axis xyz="0 0 1" />
    <limit lower="0" upper="0" effort="0" velocity="0" />
    <dynamics damping="0.1" friction="0.1" />
  </joint>

  <link name="wheel_link_1">
    <inertial>
      <origin xyz="2.22044604925031E-16 0 0.0484999999999993" rpy="0 0 0" />
      <mass value="10.3070752937469" />
      <inertia ixx="0.0955484931412842" ixy="-5.96431569855131E-18" ixz="-4.33680868994202E-18" iyy="0.0955484931412841" iyz="-2.16324915895881E-19" izz="0.176557804898947" />
    </inertial>
    <visual>
      <origin xyz="0 0 0" rpy="0 0 0" />
      <geometry>
        <mesh filename="package://vitrox_project/meshes/wheel_link_1.STL" />
      </geometry>
      <material name="">
        <color rgba="0.792156862745098 0.819607843137255 0.933333333333333 1" />
      </material>
    </visual>
    <collision>
      <origin xyz="0 0 0" rpy="0 0 0" />
      <geometry>
        <mesh filename="package://vitrox_project/meshes/wheel_link_1.STL" />
      </geometry>
    </collision>
  </link>

  <joint name="wheel_joint_1" type="continuous">
    <origin xyz="0 0.0485 -0.35" rpy="1.5708 0 0" />
    <parent link="wheel_holder_link_1" />
    <child link="wheel_link_1" />
    <axis xyz="0 0 1" />
    <dynamics damping="0.1" friction="0.1" />
  </joint>

  <link name="wheel_holder_link_2">
    <inertial>
      <origin xyz="0 1.11022302462516E-16 -0.199440219087338" rpy="0 0 0" />
      <mass value="23.1310120065877" />
      <inertia ixx="0.606465937486972" ixy="2.77555756156289E-17" ixz="2.85815090131665E-17" iyy="0.614610947650549" iyz="1.47448621135618E-17" izz="0.336166441859387" />
    </inertial>
    <visual>
      <origin xyz="0 0 0" rpy="0 0 0" />
      <geometry>
        <mesh filename="package://vitrox_project/meshes/wheel_holder_link_2.STL" />
      </geometry>
      <material name="">
        <color rgba="0.792156862745098 0.819607843137255 0.933333333333333 1" />
      </material>
    </visual>
    <collision>
      <origin xyz="0 0 0" rpy="0 0 0" />
      <geometry>
        <mesh filename="package://vitrox_project/meshes/wheel_holder_link_2.STL" />
      </geometry>
    </collision>
  </link>

  <joint name="wheel_holder_joint_2" type="continuous">
    <origin xyz="-0.79256 -0.7012 -0.64077" rpy="0 0 0" />
    <parent link="chassis_link" />
    <child link="wheel_holder_link_2" />
    <axis xyz="0 0 1" />
    <limit lower="0" upper="0" effort="0" velocity="0" />
    <dynamics damping="0.1" friction="0.1" />
  </joint>

  <link name="wheel_link_2">
    <inertial>
      <origin xyz="0 0 0.0485" rpy="0 0 0" />
      <mass value="10.3070752937469" />
      <inertia ixx="0.0955484931412842" ixy="-4.02402762013014E-18" ixz="-9.10729824887824E-18" iyy="0.0955484931412842" iyz="-2.44667161719699E-19" izz="0.176557804898947" />
    </inertial>
    <visual>
      <origin xyz="0 0 0" rpy="0 0 0" />
      <geometry>
        <mesh filename="package://vitrox_project/meshes/wheel_link_2.STL" />
      </geometry>
      <material name="">
        <color rgba="0.792156862745098 0.819607843137255 0.933333333333333 1" />
      </material>
    </visual>
    <collision>
      <origin xyz="0 0 0" rpy="0 0 0" />
      <geometry>
        <mesh filename="package://vitrox_project/meshes/wheel_link_2.STL" />
      </geometry>
    </collision>
  </link>

  <joint name="wheel_joint_2" type="continuous">
    <origin xyz="0 0.0485 -0.35" rpy="1.5708 0 0" />
    <parent link="wheel_holder_link_2" />
    <child link="wheel_link_2" />
    <axis xyz="0 0 1" />
    <dynamics damping="0.1" friction="0.1" />
  </joint>

  <link name="wheel_holder_link_3">
    <inertial>
      <origin xyz="-2.77555756156289E-17 -1.11022302462516E-16 -0.199440219087338" rpy="0 0 0" />
      <mass value="23.1310120065877" />
      <inertia ixx="0.606465937486973" ixy="-2.42861286636753E-17" ixz="4.77935503009103E-17" iyy="0.61461094765055" iyz="2.71876723033862E-17" izz="0.336166441859387" />
    </inertial>
    <visual>
      <origin xyz="0 0 0" rpy="0 0 0" />
      <geometry>
        <mesh filename="package://vitrox_project/meshes/wheel_holder_link_3.STL" />
      </geometry>
      <material name="">
        <color rgba="0.792156862745098 0.819607843137255 0.933333333333333 1" />
      </material>
    </visual>
    <collision>
      <origin xyz="0 0 0" rpy="0 0 0" />
      <geometry>
        <mesh filename="package://vitrox_project/meshes/wheel_holder_link_3.STL" />
      </geometry>
    </collision>
  </link>

  <joint name="wheel_holder_joint_3" type="continuous">
    <origin xyz="0.65801 -0.7012 -0.64077" rpy="0 0 0" />
    <parent link="chassis_link" />
    <child link="wheel_holder_link_3" />
    <axis xyz="0 0 1" />
    <limit lower="0" upper="0" effort="0" velocity="0" />
    <dynamics damping="0.1" friction="0.1" />
  </joint>

  <link name="wheel_link_3">
    <inertial>
      <origin xyz="0 5.55111512312578E-17 -0.0485" rpy="0 0 0" />
      <mass value="10.3070752937469" />
      <inertia ixx="0.0955484931412842" ixy="8.81935769125865E-19" ixz="-6.93889390390723E-18" iyy="0.0955484931412841" iyz="4.39996316746581E-19" izz="0.176557804898947" />
    </inertial>
    <visual>
      <origin xyz="0 0 0" rpy="0 0 0" />
      <geometry>
        <mesh filename="package://vitrox_project/meshes/wheel_link_3.STL" />
      </geometry>
      <material name="">
        <color rgba="0.792156862745098 0.819607843137255 0.933333333333333 1" />
      </material>
    </visual>
    <collision>
      <origin xyz="0 0 0" rpy="0 0 0" />
      <geometry>
        <mesh filename="package://vitrox_project/meshes/wheel_link_3.STL" />
      </geometry>
    </collision>
  </link>

  <joint name="wheel_joint_3" type="continuous">
    <origin xyz="0 -0.0485 -0.35" rpy="1.5708 0 0" />
    <parent link="wheel_holder_link_3" />
    <child link="wheel_link_3" />
    <axis xyz="0 0 -1" />
    <dynamics damping="0.1" friction="0.1" />
  </joint>

  <ros2_control name="GazeboSystem" type="system">
    <hardware>
      <plugin>ign_ros2_control/IgnitionSystem</plugin>
    </hardware>
    <joint name="wheel_joint" />
    <joint name="wheel_joint_1" />
    <joint name="wheel_joint_2" />
    <joint name="wheel_joint_3" />
    <joint name="wheel_holder_joint" />
    <joint name="wheel_holder_joint_1" />
    <joint name="wheel_holder_joint_2" />
    <joint name="wheel_holder_joint_3" />
  </ros2_control>

  <gazebo>
    <plugin filename="ign_ros2_control-system" name="ign_ros2_control::IgnitionROS2ControlPlugin">
      <parameters>$(find vitrox_project)/config/controllers.yaml</parameters>
    </plugin>
  </gazebo>

</robot>